Workbook

Sheet README
A1: DTC PRODUCT – GRINDING MACHINE DATABASE (A-SERIES)
A3: Quy ước tên model mới: chỉ đổi chữ cái đầu tiên B → A. Ví dụ BSC-200 → ASC-200, BSP-500 → ASP-500, BS-200 → AS-200.
A5: Thông tin | B5: Giá trị
A6: Database version | B6: 2.2.18
A7: Nguồn dữ liệu | B7: DTC-C-MayNghien-250426-demo4.pdf
A8: Phạm vi | B8: Chỉ phần MÁY NGHIỀN BỘT, PDF pages 5-20
A9: Số dòng máy | B9: 11
A10: Số model | B10: 57
A13: AI READY – Các sheet mới
A14: Materials | B14: Danh mục nguyên liệu + thuộc tính. Chỉ trường có nguồn xác minh mới nên dùng để tự động chọn máy.
A15: Material_Series_Map | B15: Điểm cộng/trừ theo tương thích nguyên liệu và dòng máy.
A16: AI_Config | B16: Trọng số, guardrail và tùy chọn hội thoại.
A17: Selection_Rules | B17: Quy tắc lọc kỹ thuật và cảnh báo.
A18: AI_Field_Map | B18: Map câu chat tiếng Việt thành trường dữ liệu chuẩn.
A19: AI_Intents | B19: Các loại yêu cầu chatbot cần nhận diện.
A20: AI_Prompt | B20: Prompt/guardrail dùng cho trợ lý AI.
A21: Chat_Examples | B21: Ví dụ câu hỏi và structured query.
A22: AI_Selection_Test | B22: Sheet test bộ chọn model trước khi code vào app.

Sheet Series
A1: series_code | B1: display_code | C1: name_vi | D1: name_en | E1: technology | F1: pdf_pages | G1: application_vi | H1: working_principle_vi | I1: notes | J1: features_vi | K1: structure_vi
A2: ASC_COARSE | B2: ASC | C2: Máy nghiền thô thực phẩm | D2: Foodstuff Industry Chili Powder Machine | E2: coarse_crusher | F2: 5 | G2: Được sử dụng rộng rãi trong các ngành: - Thực phẩm - Dược phẩm - Hóa chất Máy phù hợp để nghiền sơ bộ nguyên liệu khô và giòn, tức là biến các miếng nguyên liệu lớn thành hạt nhỏ trước khi đưa sang công đoạn nghiền mịn tiếp theo. Ví dụ nguyên liệu: - Ớt khô - Gừng khô - Tiêu - Quế - Cam thảo - Các loại dược liệu khô Máy không phù hợp với nguyên liệu có điểm hóa mềm thấp hoặc độ nhớt cao. | H2: ASC là dạng máy nghiền/cắt thô kiểu ngang. Nguyên liệu được đưa vào phễu cấp liệu, sau đó đi vào buồng nghiền. Bên trong buồng, các dao quay cắt và nghiền nguyên liệu thành kích thước nhỏ hơn. Nhờ lực ly tâm tạo ra khi dao quay, nguyên liệu sau khi đạt kích thước yêu cầu sẽ di chuyển về cửa xả. Kích thước thành phẩm được kiểm soát bằng lưới sàng. Dao nghiền được chế tạo từ thép hợp kim chịu mài mòn. | I2: Dùng làm nghiền sơ cấp.
A3: AS_SMALL_HAMMER | B3: AS | C3: Máy nghiền búa cỡ nhỏ | D3: Hammer mill | E3: high_speed_hammer | F3: 6 | G3: Sử dụng rộng rãi trong thực phẩm, hóa chất, dược phẩm và các ngành công nghiệp khác. Cấu trúc đơn giản, nhỏ gọn, dễ lắp đặt và sử dụng. Có thể tùy chỉnh lưỡi dao phù hợp nguyên liệu và yêu cầu kích thước bột. | H3: Nguyên liệu được cắt nhỏ bằng lưỡi dao quay tốc độ cao trong buồng nghiền. Độ mịn được điều chỉnh bằng cách thay đổi lưới lọc. Lưỡi dao phù hợp với nguyên liệu giàu xơ hoặc nguyên liệu thô cứng. | I3: Có lưỡi dao dạng búa và dạng cắt.
A4: ASU_UNIVERSAL | B4: ASU | C4: Máy nghiền tua-bin tốc độ cao | D4: High Speed Turbine Grinder Dried Jerusalem artichoke chips Grinding Machine | E4: universal_mill | F4: 7-8 | G4: Ứng dụng rộng trong thực phẩm, hóa chất, thức ăn chăn nuôi và dược phẩm. Kích thước bột có thể điều chỉnh bằng loại lưỡi dao, tốc độ rotor và lưới lọc. | H4: Máy ASU sử dụng đĩa tua-bin quay tốc độ cao tạo luồng khí tuần hoàn mạnh trong buồng nghiền. Luồng khí giúp tản nhiệt do ma sát, nhờ đó hạn chế tăng nhiệt khi nghiền các nguyên liệu nhạy nhiệt như rau củ sấy, gia vị. Hệ thống luồng khí đồng thời tạo vận chuyển bằng áp suất âm, giúp nguyên liệu đi qua máy ổn định, giảm hiện tượng bám dính và tắc lưới. Thiết kế này phù hợp với quá trình nghiền liên tục. | I4: Phiên bản máy đơn. | J4: 1. Nhiệt độ nghiền thấp: giảm nguy cơ cháy sém, mất mùi, biến màu và suy giảm chất dinh dưỡng. 2. Phạm vi nguyên liệu rộng: có 3 loại rotor có thể thay đổi, dùng cho ngũ cốc, gia vị, thảo dược và rau củ khô. 3. Dễ tháo vệ sinh: rotor tua-bin có thể tháo nhanh, thuận lợi vệ sinh và hạn chế nhiễm chéo giữa các mẻ.
A5: ASG_UNIVERSAL_SYSTEM | B5: ASG | C5: Máy nghiền búa tự hút | D5: Self-Suction Hammer Mill System | E5: universal_mill_with_dust_system | F5: 7-8 | G5: Ứng dụng rộng trong thực phẩm, hóa chất, thức ăn chăn nuôi và dược phẩm. Máy nghiền tích hợp hệ thống gió/thu bụi dạng lốc xoáy. | H5: Nguyên lý nghiền Nguyên liệu đi từ phễu cấp liệu vào buồng nghiền. Bên trong máy, đĩa nghiền/búa quay với tốc độ cao làm nguyên liệu bị: Va đập → văng vào vành răng cố định → cắt → va đập lại → nghiền nhỏ Trang mô tả quá trình nghiền là sự kết hợp của: - lực va đập, - lực cắt, - lực nghiền/chà xát. Sau khi được nghiền nhỏ, nhờ áp suất âm do quạt hút tạo ra, bột được hút ra khỏi buồng nghiền và chuyển qua: Buồng nghiền → lưới sàng → đường ống → cyclone → thu sản phẩm Một lượng nhỏ bụi rất mịn sẽ được pulse dust collector thu hồi. Chức năng phân loại kích thước - chức năng nghiền. - phân loại. - sàng. - cắt ly tâm. Nhờ vậy kích thước hạt thành phẩm có thể được kiểm soát. Tuy nhiên, với ASG này, việc kiểm soát kích thước vẫn phụ thuộc đáng kể vào lưới sàng, khác với ASP Air Classifier Mill sử dụng bánh phân cấp tốc độ cao. | I5: Kèm hệ thống gió khử bụi. | K5: Theo Brightsail, bộ BSG self-priming grinding unit gồm: - Máy nghiền chính - Thiết bị phụ trợ - Đường ống vận chuyển - Tủ/thiết bị điều khiển điện - Bộ cấp liệu - Cyclone separator - Bộ lọc túi / thu bụi - Hệ thống hút khí Máy phụ trợ sử dụng cyclone kết hợp bag filter và air collector để thu hồi bột và bụi mịn.
A6: ASP_ULTRAFINE | B6: ASP | C6: Máy nghiền siêu mịn | D6: Air Classifier Mill | E6: air_classifier_mill | F6: 9-11 | G6: Máy nghiền chuyên dụng để sản xuất bột siêu mịn. Kết hợp làm mát bột và phân loại không khí có kiểm soát; dùng trong hóa chất, thực phẩm, khoáng sản và sơn phủ. | H6: Nguyên liệu được cấp vào buồng nghiền bằng vít tải cấp liệu. Trong buồng nghiền, hạt nguyên liệu bị nghiền do: - va đập với rotor quay tốc độ cao; - va đập với liner cố định; - lực cắt và va chạm liên tục. Sau đó bột được cuốn theo dòng khí làm mát và vận chuyển do quạt hút tạo ra. Hỗn hợp khí–bột đi tới bánh phân ly động tích hợp ngay trong máy. Tại vùng phân ly: - Hạt quá thô bị bánh phân ly loại ra và quay trở lại vùng nghiền để nghiền tiếp. - Hạt đạt yêu cầu đi xuyên qua bánh phân ly, ra khỏi máy và được cyclone thu hồi. - Bụi cực mịn còn lại được chuyển tới hộp thu bụi, giúp hệ thống vận hành hạn chế phát tán bụi. Độ mịn lớn nhất của sản phẩm được điều khiển chủ yếu bằng tốc độ bánh phân ly và có thể điều chỉnh trong khi máy đang hoạt động. | I6: Có phân loại trên/dưới; dao vuông cho bột siêu mịn, nguyên liệu cứng/giàu xơ; dao hình trụ cho vật liệu giòn/dễ vỡ/kết tinh. | J6: - Nghiền + phân ly trong cùng một máy - Điều chỉnh kích thước hạt bằng lưu lượng khí và tốc độ rotor phân ly - Có thể thay đổi độ mịn trong khi máy đang chạy - Thiết kế gọn, tiết kiệm diện tích - Có thể sử dụng kết hợp chiller công nghiệp - Phân bố kích thước hạt hẹp - Kiểm soát kích thước hạt lớn nhất tốt - Dễ vệ sinh và bảo trì - Tiêu thụ năng lượng riêng thấp
A7: ASZ_PIN | B7: ASZ | C7: Máy nghiền pin | D7: High speed pin mill | E7: pin_mill | F7: 11-13 | G7: Máy nghiền va đập mịn với hai đĩa chốt quay. Có thể xử lý sản phẩm ẩm, dầu và dính. Buồng rộng phù hợp các sản phẩm này; có thể kết nối nitơ lỏng để làm mát. Có thể hoạt động độc lập và phù hợp sản phẩm dạng nhão như bột mịn cacao. | H7: Hai đĩa chốt quay tạo tốc độ tương đối cao; độ mịn điều chỉnh bằng thay đổi tốc độ các đĩa. Lực ly tâm hỗ trợ xử lý nguyên liệu ẩm, dầu và dính. | I7: Loại A cho bột chảy kém như bột gia vị; Loại B cho bột có khả năng chảy tốt.
A8: ASF_AS_HAMMER | B8: AS | C8: Máy nghiền búa | D8: Hammer mill | E8: hammer_mill | F8: 14-15 | G8: Sử dụng rộng rãi trong nhà máy thực phẩm và dược phẩm; phù hợp nghiền các nguyên liệu như tiêu, gia vị, hạt thì là. | H8: Nguyên liệu được nghiền nhờ chuyển động tốc độ cao giữa búa/dao động và đĩa cố định. Trong buồng nghiền có lưới sàng: - Hạt có kích thước nhỏ hơn lỗ sàng sẽ đi qua lưới và thoát khỏi buồng nghiền dưới tác dụng của lực ly tâm. - Hạt còn quá lớn sẽ tiếp tục ở lại trong buồng nghiền để được nghiền tiếp. Như vậy, kích thước thành phẩm được điều chỉnh chủ yếu thông qua kích thước lỗ sàng. | I8: AS-200 trở lên có cấu hình hệ thống theo bảng. | K8: Hệ thống gồm các bộ phận chính: - Cụm máy nghiền - Cyclone tách liệu - Hộp thu bụi - Quạt hút - Tủ điều khiển điện - Hệ thống đường ống kết nối Máy sử dụng chuyển động tương đối giữa bộ phận cố định và búa/dao chuyển động để nghiền nguyên liệu bằng tác động va đập kết hợp lực ly tâm. Nhà sản xuất cho biết máy phù hợp với các nguyên liệu như tiêu, gia vị, hạt thì là...
A9: ASDF_MULTISTAGE | B9: ASDF | C9: Máy nghiền búa nhiều tầng | D9: 3-Stage advanced hammer mill unit | E9: multi_stage_hammer | F9: 15-17 | G9: Nghiền ba lần trong cùng buồng nghiền qua ba vùng: thô, trung bình và mịn. Có thể nghiền bột mịn trực tiếp từ nguyên liệu thô lớn; tích hợp cyclone, lọc bụi, quạt hút và tủ điều khiển. | H9: Điểm đặc biệt: nghiền 3 tầng trong cùng một buồng Đây là điểm quan trọng nhất của ASDF. Bộ phận nghiền tích hợp 3 vùng nghiền liên tiếp: 1. Vùng nghiền thô 2. Vùng nghiền trung gian 3. Vùng nghiền mịn Mỗi tầng có một bộ dao và một lớp liner riêng. Nguyên liệu đi qua lần lượt ba nhóm dao quay tốc độ cao và được nghiền 3 lần trong cùng một buồng nghiền. Giữa vùng nghiền trung gian và vùng nghiền mịn có một cơ cấu nhằm ngăn hạt thô đi trực tiếp sang khu vực nghiền mịn, giúp kiểm soát độ mịn của sản phẩm tốt hơn. | I9: PDF trang 17 hiển thị tiêu đề 'BSC Máy nghiền thô' nhưng nội dung, hình và bảng đều là BSDF; database giữ BSDF và ghi nhận trong bảng data_corrections. | K9: Một bộ BSDF hoàn chỉnh gồm: - Cụm nghiền - Cyclone thu hồi sản phẩm - Hệ thống thu bụi xung pulse - Quạt hút - Tủ điều khiển điện Nguyên liệu đi vào buồng nghiền. Sau khi nghiền, luồng khí từ quạt đưa bột tới cyclone để tách và xả sản phẩm. Phần bột siêu mịn còn lại trong luồng khí được thu ở hộp lọc bụi. Toàn bộ quá trình được thiết kế làm việc liên tục và hạn chế phát sinh bụi.
A10: AS_ROLLER | B10: Roller mill | C10: Máy nghiền trục lăn | D10: AS Series Spice Pulverizer Set | E10: roller_mill | F10: 18 | G10: Dùng rộng rãi trong thực phẩm, đặc biệt cho nguyên liệu dầu như vừng, lạc (đậu phộng) và hạnh nhân; có thể nghiền thành bột khoảng 10-40 mesh. | H10: Nguyên liệu thô được đưa từ phễu nạp liệu vào khu vực trục nghiền và được nghiền thành dạng bột. Bằng cách điều chỉnh khoảng cách giữa hai trục nghiền, người dùng có thể thu được thành phẩm với kích thước hạt theo mong muốn. | I10: 3-roller và 4-roller.
A11: ASK_JET | B11: ASK | C11: Máy nghiền phản lực khí siêu mịn | D11: Powder Air Jet Mill | E11: jet_mill | F11: 19 | G11: Ứng dụng chính của ASK Jet Mill phù hợp cho: - Vật liệu có tính mài mòn - Nguyên liệu có tính dính - Chất độn khoáng - Chất độn ceramic/gốm - Thực phẩm - Hóa chất - Hóa chất nông nghiệp | H11: Air Jet Mill là máy nghiền sử dụng khí nén tốc độ cao để nghiền các vật liệu dạng khô thành bột siêu mịn. Cấu tạo chính bao gồm vít cấp liệu, vòi phun nghiền, buồng nghiền và buồng phân cấp. Có thể hình dung nguyên lý: Nguyên liệu → vít cấp liệu → buồng nghiền → khí nén tốc độ cao → va chạm giữa các hạt → phân cấp → cyclone → bộ thu bụi Bước 1 – Cấp liệu Vít tải có tốc độ điều chỉnh, đưa nguyên liệu vào Jet Mill một cách ổn định và liên tục. Bước 2 – Gia tốc bằng khí nén Khí nén đi qua các vòi phun được thiết kế đặc biệt, đạt vận tốc rất cao. Luồng khí cuốn nguyên liệu vào vùng nghiền. Bước 3 – Nghiền bằng va chạm Điểm rất quan trọng của Jet Mill là: Không chủ yếu dùng dao, búa hay pin để nghiền. Các hạt nguyên liệu được khí nén gia tốc và va chạm với nhau nhiều lần, từ đó tự vỡ nhỏ thành bột. Đây là khác biệt lớn so với ASP Air Classifier Mill hoặc ASZ Pin Mill. Bước 4 – Phân cấp Sau khi nghiền, bột được luồng khí đưa lên buồng phân cấp. Tại đây hạt chịu hai lực chính: - Lực ly tâm do bánh phân cấp quay tốc độ cao. - Lực hút khí động do hệ thống quạt hút tạo ra. Bước 5 – Tách bột mịn và bột thô Nếu hạt đã đủ mịn, lực hút khí thắng lực ly tâm, hạt đi qua bánh phân cấp và tiếp tục đến: Classifier → Cyclone → Dust Collector để thu hồi sản phẩm. Nếu hạt còn quá thô, bánh phân cấp sẽ loại nó ra và đưa trở lại buồng nghiền để tiếp tục nghiền. | I11: Đơn vị tiêu thụ khí nén được giữ nguyên theo PDF là m3/giây và được đánh dấu cần xác minh trước khi dùng thiết kế.
A12: AS_CRYOGENIC | B12: AS | C12: Máy nghiền siêu lạnh | D12: Low Temperature Spice Cryogenic Pin Mill Grinder | E12: cryogenic_grinding | F12: 20 | G12: Máy có phạm vi ứng dụng khá rộng, gồm: - Thực phẩm và sản phẩm chăm sóc sức khỏe: gia vị, chiết xuất động thực vật, thuốc đông dược/thành phẩm y học cổ truyền, các thành phần tự nhiên và tổng hợp - Ngành hóa chất và sơn phủ: ví dụ bột dùng cho lớp phủ Teflon, PA, PC, PU, PP, PE - Tái chế: nhựa có điểm nóng chảy thấp, vật liệu tự bôi trơn cao, cao su phế liệu, cao su nguyên sinh… | H12: Nguồn lạnh trao đổi nhiệt với vật liệu làm vật liệu hạ nhiệt và trở nên giòn. Sau đó vật liệu được va đập, cắt và ma sát trong buồng nghiền để tạo thành hạt mịn. Trang sản phẩm còn nói kích thước có thể đạt tới mức micron trong mô tả nguyên lý nghiền. | I12: Nhiệt độ nguồn ghi -196 đến 0 °C.
A13: ASF_FITZ_MILL | B13: ASF | C13: Máy nghiền dược liệu | D13: Pharmaceutical Fitz Mill | E13: fitz_mill | F13: 14-15 | G13: Sử dụng trong nhiều lĩnh vực như: - Dược phẩm - Thực phẩm - Hóa chất - Dược liệu - Lá trà và các loại lá/thảo mộc khô Các bộ phận tiếp xúc trực tiếp với nguyên liệu đều được làm bằng thép không gỉ, có khả năng chống ăn mòn tốt. Thân máy được thiết kế kín hoàn toàn, giúp thuận tiện cho việc vệ sinh. Bề mặt bên trong được xử lý phẳng và nhẵn để đáp ứng tốt hơn các yêu cầu vệ sinh khi sản xuất dược phẩm, thực phẩm và hóa chất, theo định hướng tiêu chuẩn GMP mà nhà sản xuất đề cập. | H13: ASF là thiết bị nghiền tốc độ cao. Nguyên liệu được nghiền nhờ các dao quay tốc độ cao. Dao có hai phía làm việc khác nhau: - Một phía có cạnh sắc để cắt - Phía còn lại hoạt động như dao va đập Trong quá trình quay tốc độ cao, nguyên liệu liên tục bị: Cắt → va đập → nghiền nhỏ → đi qua lưới sàng → thành phẩm Nhà sản xuất cho biết có thể sử dụng dao với kích thước và hình dạng khác nhau tùy theo loại nguyên liệu. Kích thước bột thành phẩm được điều chỉnh bằng hai cách chính: Thay lưới sàng hoặc thay đổi tốc độ quay. | I13: Dạng máy đơn (ASF-15, ASF-32); tách từ dòng ASF/AS. | J13: 1. Dao quay tốc độ cao: Dao nghiền quay ở tốc độ cao để cắt và nghiền nguyên liệu cho đến khi kích thước hạt nhỏ hơn lỗ của tấm lưới sàng. 2. Có thể điều chỉnh tốc độ: Tốc độ quay có thể thay đổi để phù hợp với từng loại nguyên liệu và kích thước thành phẩm yêu cầu. 3. Sử dụng lưới đục lỗ: Máy sử dụng perforated plate screen – tấm sàng đục lỗ. Có thể lựa chọn kích thước lỗ sàng phù hợp với yêu cầu sản xuất.

Sheet Models
A1: machine_id | B1: ID Check | C1: series_code | D1: model | E1: active | F1: pdf_page | G1: capacity_min_kg_h | H1: capacity_max_kg_h | I1: input_size_max_mm | J1: input_size_note | K1: fineness_min | L1: fineness_max | M1: fineness_unit | N1: main_motor_kw_min | O1: main_motor_kw_max | P1: speed_rpm_min | Q1: speed_rpm_max | R1: length_mm | S1: width_mm | T1: height_mm | U1: weight_kg | V1: source_document | W1: edit_note
A2: ASC_COARSE__ASC-200 | B2: OK | C2: ASC_COARSE | D2: ASC-200 | E2: TRUE | F2: 5 | G2: 80 | H2: 300 | I2: 100 | J2: < 100 mm | K2: 0.5 | L2: 20 | M2: mm | N2: 3 | O2: 3 | P2: 530 | Q2: 530 | R2: 600 | S2: 500 | T2: 1228 | U2: 200 | V2: DTC-C-MayNghien-250426-demo4.pdf | W2: Đổi ký tự đầu của model từ B thành A.
A3: ASC_COARSE__ASC-300 | B3: OK | C3: ASC_COARSE | D3: ASC-300 | E3: TRUE | F3: 5 | G3: 100 | H3: 800 | I3: 100 | J3: < 100 mm | K3: 0.5 | L3: 20 | M3: mm | N3: 5.5 | O3: 5.5 | P3: 530 | Q3: 530 | R3: 720 | S3: 700 | T3: 1303 | U3: 300 | V3: DTC-C-MayNghien-250426-demo4.pdf | W3: Đổi ký tự đầu của model từ B thành A.
A4: ASC_COARSE__ASC-400 | B4: OK | C4: ASC_COARSE | D4: ASC-400 | E4: TRUE | F4: 5 | G4: 200 | H4: 1000 | I4: 100 | J4: < 100 mm | K4: 0.5 | L4: 20 | M4: mm | N4: 7.5 | O4: 7.5 | P4: 530 | Q4: 530 | R4: 900 | S4: 700 | T4: 1306 | U4: 380 | V4: DTC-C-MayNghien-250426-demo4.pdf | W4: Đổi ký tự đầu của model từ B thành A.
A5: ASC_COARSE__ASC-600 | B5: OK | C5: ASC_COARSE | D5: ASC-600 | E5: TRUE | F5: 5 | G5: 500 | H5: 1500 | I5: 100 | J5: < 100 mm | K5: 0.5 | L5: 20 | M5: mm | N5: 11 | O5: 11 | P5: 530 | Q5: 530 | R5: 1020 | S5: 700 | T5: 1306 | U5: 500 | V5: DTC-C-MayNghien-250426-demo4.pdf | W5: Đổi ký tự đầu của model từ B thành A.
A6: ASC_COARSE__ASC-1000 | B6: OK | C6: ASC_COARSE | D6: ASC-1000 | E6: TRUE | F6: 5 | G6: 1000 | H6: 2500 | I6: 100 | J6: < 100 mm | K6: 0.5 | L6: 20 | M6: mm | N6: 15 | O6: 15 | P6: 540 | Q6: 540 | R6: 1330 | S6: 850 | T6: 1826 | U6: 1000 | V6: DTC-C-MayNghien-250426-demo4.pdf | W6: Đổi ký tự đầu của model từ B thành A.
A7: AS_SMALL_HAMMER__AS-180 | B7: OK | C7: AS_SMALL_HAMMER | D7: AS-180 | E7: TRUE | F7: 6 | G7: 3 | H7: 50 | I7: 10 | J7: <10 mm cho nguyên liệu hạt; <15×40×2 mm cho nguyên liệu lá | K7: 10 | L7: 120 | M7: mesh | N7: 2.2 | O7: 2.2 | P7: 5900 | Q7: 8600 | R7: 840 | S7: 470 | T7: 1020 | U7: 112 | V7: DTC-C-MayNghien-250426-demo4.pdf | W7: Đổi ký tự đầu của model từ B thành A.
A8: AS_SMALL_HAMMER__AS-250 | B8: OK | C8: AS_SMALL_HAMMER | D8: AS-250 | E8: TRUE | F8: 6 | G8: 10 | H8: 100 | I8: 10 | J8: <10 mm cho nguyên liệu hạt; <15×40×2 mm cho nguyên liệu lá | K8: 10 | L8: 120 | M8: mesh | N8: 5.5 | O8: 5.5 | P8: 4200 | Q8: 6200 | R8: 930 | S8: 600 | T8: 1200 | U8: 210 | V8: DTC-C-MayNghien-250426-demo4.pdf | W8: Đổi ký tự đầu của model từ B thành A.
A9: AS_SMALL_HAMMER__AS-350 | B9: OK | C9: AS_SMALL_HAMMER | D9: AS-350 | E9: TRUE | F9: 6 | G9: 30 | H9: 300 | I9: 10 | J9: <10 mm cho nguyên liệu hạt; <15×40×2 mm cho nguyên liệu lá | K9: 10 | L9: 120 | M9: mesh | N9: 11 | O9: 11 | P9: 2200 | Q9: 4400 | R9: 1150 | S9: 700 | T9: 1600 | U9: 430 | V9: DTC-C-MayNghien-250426-demo4.pdf | W9: Đổi ký tự đầu của model từ B thành A.
A10: ASU_UNIVERSAL__ASU-20 | B10: OK | C10: ASU_UNIVERSAL | D10: ASU-20 | E10: TRUE | F10: 8 | G10: 20 | H10: 150 | I10: 6 | J10: < 6 mm | K10: 20 | L10: 120 | M10: mesh | N10: 4 | O10: 4 | R10: 550 | S10: 550 | T10: 1200 | V10: DTC-C-MayNghien-250426-demo4.pdf | W10: Đổi ký tự đầu của model từ B thành A.
A11: ASU_UNIVERSAL__ASU-30 | B11: OK | C11: ASU_UNIVERSAL | D11: ASU-30 | E11: TRUE | F11: 8 | G11: 30 | H11: 300 | I11: 10 | J11: < 10 mm | K11: 20 | L11: 120 | M11: mesh | N11: 7.5 | O11: 7.5 | R11: 650 | S11: 650 | T11: 1520 | V11: DTC-C-MayNghien-250426-demo4.pdf | W11: Đổi ký tự đầu của model từ B thành A.
A12: ASU_UNIVERSAL__ASU-40 | B12: OK | C12: ASU_UNIVERSAL | D12: ASU-40 | E12: TRUE | F12: 8 | G12: 50 | H12: 400 | I12: 10 | J12: < 10 mm | K12: 20 | L12: 120 | M12: mesh | N12: 11 | O12: 11 | R12: 780 | S12: 780 | T12: 1600 | V12: DTC-C-MayNghien-250426-demo4.pdf | W12: Đổi ký tự đầu của model từ B thành A.
A13: ASU_UNIVERSAL__ASU-50 | B13: OK | C13: ASU_UNIVERSAL | D13: ASU-50 | E13: TRUE | F13: 8 | G13: 100 | H13: 800 | I13: 10 | J13: < 10 mm | K13: 20 | L13: 120 | M13: mesh | N13: 15 | O13: 15 | R13: 850 | S13: 850 | T13: 1650 | V13: DTC-C-MayNghien-250426-demo4.pdf | W13: Đổi ký tự đầu của model từ B thành A.
A14: ASG_UNIVERSAL_SYSTEM__ASG-300 | B14: OK | C14: ASG_UNIVERSAL_SYSTEM | D14: ASG-300 | E14: TRUE | F14: 8 | G14: 50 | H14: 400 | K14: 10 | L14: 120 | M14: mesh | N14: 7.5 | O14: 7.5 | P14: 4000 | Q14: 4000 | V14: DTC-C-MayNghien-250426-demo4.pdf | W14: Đổi ký tự đầu của model từ B thành A.
A15: ASG_UNIVERSAL_SYSTEM__ASG-400 | B15: OK | C15: ASG_UNIVERSAL_SYSTEM | D15: ASG-400 | E15: TRUE | F15: 8 | G15: 100 | H15: 800 | K15: 10 | L15: 120 | M15: mesh | N15: 11 | O15: 11 | P15: 3400 | Q15: 3400 | V15: DTC-C-MayNghien-250426-demo4.pdf | W15: Đổi ký tự đầu của model từ B thành A.
A16: ASG_UNIVERSAL_SYSTEM__ASG-500 | B16: OK | C16: ASG_UNIVERSAL_SYSTEM | D16: ASG-500 | E16: TRUE | F16: 8 | G16: 200 | H16: 1000 | K16: 10 | L16: 120 | M16: mesh | N16: 15 | O16: 18.5 | P16: 3000 | Q16: 3000 | V16: DTC-C-MayNghien-250426-demo4.pdf | W16: Đổi ký tự đầu của model từ B thành A.
A17: ASG_UNIVERSAL_SYSTEM__ASG-600 | B17: OK | C17: ASG_UNIVERSAL_SYSTEM | D17: ASG-600 | E17: TRUE | F17: 8 | G17: 300 | H17: 1500 | K17: 10 | L17: 120 | M17: mesh | N17: 22 | O17: 30 | P17: 2800 | Q17: 2800 | V17: DTC-C-MayNghien-250426-demo4.pdf | W17: Đổi ký tự đầu của model từ B thành A.
A18: ASG_UNIVERSAL_SYSTEM__ASG-850 | B18: OK | C18: ASG_UNIVERSAL_SYSTEM | D18: ASG-850 | E18: TRUE | F18: 8 | G18: 450 | H18: 2000 | K18: 10 | L18: 120 | M18: mesh | N18: 37 | O18: 45 | P18: 2100 | Q18: 2100 | V18: DTC-C-MayNghien-250426-demo4.pdf | W18: Đổi ký tự đầu của model từ B thành A.
A19: ASG_UNIVERSAL_SYSTEM__ASG-1000 | B19: OK | C19: ASG_UNIVERSAL_SYSTEM | D19: ASG-1000 | E19: TRUE | F19: 8 | G19: 600 | H19: 3000 | K19: 10 | L19: 120 | M19: mesh | N19: 55 | O19: 55 | P19: 1400 | Q19: 1400 | V19: DTC-C-MayNghien-250426-demo4.pdf | W19: Đổi ký tự đầu của model từ B thành A.
A20: ASP_ULTRAFINE__ASP-250 | B20: OK | C20: ASP_ULTRAFINE | D20: ASP-250 | E20: TRUE | F20: 11 | G20: 10 | H20: 100 | I20: 8 | J20: < 8 mm | K20: 60 | L20: 2500 | M20: mesh | N20: 5.5 | O20: 5.5 | P20: 8400 | Q20: 8400 | V20: DTC-C-MayNghien-250426-demo4.pdf | W20: Đổi ký tự đầu của model từ B thành A.
A21: ASP_ULTRAFINE__ASP-350 | B21: OK | C21: ASP_ULTRAFINE | D21: ASP-350 | E21: TRUE | F21: 11 | G21: 20 | H21: 200 | I21: 15 | J21: < 15 mm | K21: 60 | L21: 2500 | M21: mesh | N21: 15 | O21: 18.5 | P21: 6500 | Q21: 6500 | V21: DTC-C-MayNghien-250426-demo4.pdf | W21: Đổi ký tự đầu của model từ B thành A.
A22: ASP_ULTRAFINE__ASP-450 | B22: OK | C22: ASP_ULTRAFINE | D22: ASP-450 | E22: TRUE | F22: 11 | G22: 40 | H22: 500 | I22: 15 | J22: < 15 mm | K22: 60 | L22: 2500 | M22: mesh | N22: 18.5 | O22: 22 | P22: 5600 | Q22: 5600 | V22: DTC-C-MayNghien-250426-demo4.pdf | W22: Đổi ký tự đầu của model từ B thành A.
A23: ASP_ULTRAFINE__ASP-500 | B23: OK | C23: ASP_ULTRAFINE | D23: ASP-500 | E23: TRUE | F23: 11 | G23: 50 | H23: 800 | I23: 15 | J23: < 15 mm | K23: 60 | L23: 2500 | M23: mesh | N23: 30 | O23: 37 | P23: 4400 | Q23: 4400 | V23: DTC-C-MayNghien-250426-demo4.pdf | W23: Đổi ký tự đầu của model từ B thành A.
A24: ASP_ULTRAFINE__ASP-750 | B24: OK | C24: ASP_ULTRAFINE | D24: ASP-750 | E24: TRUE | F24: 11 | G24: 120 | H24: 1800 | I24: 15 | J24: < 15 mm | K24: 60 | L24: 2500 | M24: mesh | N24: 55 | O24: 75 | P24: 3100 | Q24: 3100 | V24: DTC-C-MayNghien-250426-demo4.pdf | W24: Đổi ký tự đầu của model từ B thành A.
A25: ASP_ULTRAFINE__ASP-900 | B25: OK | C25: ASP_ULTRAFINE | D25: ASP-900 | E25: TRUE | F25: 11 | G25: 800 | H25: 2500 | I25: 20 | J25: < 20 mm | K25: 60 | L25: 2500 | M25: mesh | N25: 90 | O25: 90 | P25: 2450 | Q25: 2450 | V25: DTC-C-MayNghien-250426-demo4.pdf | W25: Đổi ký tự đầu của model từ B thành A.
A26: ASP_ULTRAFINE__ASP-1000 | B26: OK | C26: ASP_ULTRAFINE | D26: ASP-1000 | E26: TRUE | F26: 11 | G26: 1000 | H26: 3600 | I26: 20 | J26: < 20 mm | K26: 60 | L26: 2500 | M26: mesh | N26: 110 | O26: 110 | P26: 2450 | Q26: 2450 | V26: DTC-C-MayNghien-250426-demo4.pdf | W26: Đổi ký tự đầu của model từ B thành A.
A27: ASZ_PIN__ASZ-250 | B27: OK | C27: ASZ_PIN | D27: ASZ-250 | E27: TRUE | F27: 13 | G27: 50 | H27: 300 | I27: 5 | J27: < 5 mm | K27: 40 | L27: 500 | M27: mesh | N27: 11 | O27: 11 | P27: 17000 | Q27: 17000 | V27: DTC-C-MayNghien-250426-demo4.pdf | W27: Đổi ký tự đầu của model từ B thành A.
A28: ASZ_PIN__ASZ-350 | B28: OK | C28: ASZ_PIN | D28: ASZ-350 | E28: TRUE | F28: 13 | G28: 100 | H28: 1000 | I28: 15 | J28: < 15 mm | K28: 40 | L28: 500 | M28: mesh | N28: 15 | O28: 18.5 | P28: 12000 | Q28: 12000 | V28: DTC-C-MayNghien-250426-demo4.pdf | W28: Đổi ký tự đầu của model từ B thành A.
A29: ASZ_PIN__ASZ-450 | B29: OK | C29: ASZ_PIN | D29: ASZ-450 | E29: TRUE | F29: 13 | G29: 300 | H29: 1500 | I29: 15 | J29: < 15 mm | K29: 40 | L29: 500 | M29: mesh | N29: 22 | O29: 30 | P29: 9600 | Q29: 9600 | V29: DTC-C-MayNghien-250426-demo4.pdf | W29: Đổi ký tự đầu của model từ B thành A.
A30: ASZ_PIN__ASZ-550 | B30: OK | C30: ASZ_PIN | D30: ASZ-550 | E30: TRUE | F30: 13 | G30: 600 | H30: 2000 | I30: 15 | J30: < 15 mm | K30: 40 | L30: 500 | M30: mesh | N30: 30 | O30: 37 | P30: 8400 | Q30: 8400 | V30: DTC-C-MayNghien-250426-demo4.pdf | W30: Đổi ký tự đầu của model từ B thành A.
A31: ASZ_PIN__ASZ-630 | B31: OK | C31: ASZ_PIN | D31: ASZ-630 | E31: TRUE | F31: 13 | G31: 1000 | H31: 2500 | I31: 25 | J31: < 25 mm | K31: 40 | L31: 500 | M31: mesh | N31: 55 | O31: 55 | P31: 6600 | Q31: 6600 | V31: DTC-C-MayNghien-250426-demo4.pdf | W31: Đổi ký tự đầu của model từ B thành A.
A32: ASF_AS_HAMMER__ASF-15 | B32: OK | C32: ASF_FITZ_MILL | D32: ASF-15 | E32: TRUE | F32: 15 | G32: 50 | H32: 300 | K32: 12 | L32: 120 | M32: mesh | N32: 7.5 | O32: 7.5 | V32: DTC-C-MayNghien-250426-demo4.pdf | W32: Đổi ký tự đầu của model từ B thành A.
A33: ASF_AS_HAMMER__ASF-32 | B33: OK | C33: ASF_FITZ_MILL | D33: ASF-32 | E33: TRUE | F33: 15 | G33: 100 | H33: 400 | K33: 12 | L33: 120 | M33: mesh | N33: 11 | O33: 11 | V33: DTC-C-MayNghien-250426-demo4.pdf | W33: Đổi ký tự đầu của model từ B thành A.
A34: ASF_AS_HAMMER__AS-200 | B34: OK | C34: ASF_AS_HAMMER | D34: AS-200 | E34: TRUE | F34: 15 | G34: 50 | H34: 300 | K34: 12 | L34: 120 | M34: mesh | N34: 7.5 | O34: 7.5 | V34: DTC-C-MayNghien-250426-demo4.pdf | W34: Đổi ký tự đầu của model từ B thành A.
A35: ASF_AS_HAMMER__AS-320 | B35: OK | C35: ASF_AS_HAMMER | D35: AS-320 | E35: TRUE | F35: 15 | G35: 100 | H35: 400 | K35: 12 | L35: 120 | M35: mesh | N35: 11 | O35: 11 | V35: DTC-C-MayNghien-250426-demo4.pdf | W35: Đổi ký tự đầu của model từ B thành A.
A36: ASF_AS_HAMMER__AS-400 | B36: OK | C36: ASF_AS_HAMMER | D36: AS-400 | E36: TRUE | F36: 15 | G36: 100 | H36: 1200 | K36: 12 | L36: 120 | M36: mesh | N36: 22 | O36: 37 | V36: DTC-C-MayNghien-250426-demo4.pdf | W36: Đổi ký tự đầu của model từ B thành A.
A37: ASF_AS_HAMMER__AS-630 | B37: OK | C37: ASF_AS_HAMMER | D37: AS-630 | E37: TRUE | F37: 15 | G37: 300 | H37: 1800 | K37: 12 | L37: 120 | M37: mesh | N37: 37 | O37: 45 | V37: DTC-C-MayNghien-250426-demo4.pdf | W37: Đổi ký tự đầu của model từ B thành A.
A38: ASF_AS_HAMMER__AS-880 | B38: OK | C38: ASF_AS_HAMMER | D38: AS-880 | E38: TRUE | F38: 15 | G38: 400 | H38: 2000 | K38: 12 | L38: 120 | M38: mesh | N38: 55 | O38: 55 | V38: DTC-C-MayNghien-250426-demo4.pdf | W38: Đổi ký tự đầu của model từ B thành A.
A39: ASF_AS_HAMMER__AS-1000 | B39: OK | C39: ASF_AS_HAMMER | D39: AS-1000 | E39: TRUE | F39: 15 | G39: 1000 | H39: 3000 | K39: 12 | L39: 120 | M39: mesh | N39: 75 | O39: 75 | V39: DTC-C-MayNghien-250426-demo4.pdf | W39: Đổi ký tự đầu của model từ B thành A.
A40: ASDF_MULTISTAGE__ASDF-350 | B40: OK | C40: ASDF_MULTISTAGE | D40: ASDF-350 | E40: TRUE | F40: 17 | G40: 100 | H40: 200 | K40: 20 | L40: 150 | M40: mesh | N40: 22 | O40: 22 | P40: 3500 | Q40: 4500 | V40: DTC-C-MayNghien-250426-demo4.pdf | W40: Đổi ký tự đầu của model từ B thành A.
...

Sheet Extra_Specs
A1: machine_id | B1: series_code | C1: model | D1: spec_key | E1: spec_value_number | F1: spec_value_text | G1: unit | H1: source_pdf_page | I1: note
A2: AS_SMALL_HAMMER__AS-180 | B2: BS_SMALL_HAMMER | C2: AS-180 | D2: chamber_diameter_mm | E2: 200 | G2: mm | H2: 6
A3: AS_SMALL_HAMMER__AS-250 | B3: BS_SMALL_HAMMER | C3: AS-250 | D3: chamber_diameter_mm | E3: 270 | G3: mm | H3: 6
A4: AS_SMALL_HAMMER__AS-350 | B4: BS_SMALL_HAMMER | C4: AS-350 | D4: chamber_diameter_mm | E4: 380 | G4: mm | H4: 6
A5: ASG_UNIVERSAL_SYSTEM__ASG-300 | B5: BSG_UNIVERSAL_SYSTEM | C5: ASG-300 | D5: blower_motor_kw | E5: 3 | G5: kW | H5: 8
A6: ASG_UNIVERSAL_SYSTEM__ASG-300 | B6: BSG_UNIVERSAL_SYSTEM | C6: ASG-300 | D6: discharge_motor_kw_min | E6: 0.55 | G6: kW | H6: 8
A7: ASG_UNIVERSAL_SYSTEM__ASG-300 | B7: BSG_UNIVERSAL_SYSTEM | C7: ASG-300 | D7: discharge_motor_kw_max | E7: 0.75 | G7: kW | H7: 8
A8: ASG_UNIVERSAL_SYSTEM__ASG-400 | B8: BSG_UNIVERSAL_SYSTEM | C8: ASG-400 | D8: blower_motor_kw | E8: 3 | G8: kW | H8: 8
A9: ASG_UNIVERSAL_SYSTEM__ASG-400 | B9: BSG_UNIVERSAL_SYSTEM | C9: ASG-400 | D9: discharge_motor_kw_min | E9: 0.75 | G9: kW | H9: 8
A10: ASG_UNIVERSAL_SYSTEM__ASG-400 | B10: BSG_UNIVERSAL_SYSTEM | C10: ASG-400 | D10: discharge_motor_kw_max | E10: 0.75 | G10: kW | H10: 8
A11: ASG_UNIVERSAL_SYSTEM__ASG-500 | B11: BSG_UNIVERSAL_SYSTEM | C11: ASG-500 | D11: blower_motor_kw | E11: 5.5 | G11: kW | H11: 8
A12: ASG_UNIVERSAL_SYSTEM__ASG-500 | B12: BSG_UNIVERSAL_SYSTEM | C12: ASG-500 | D12: discharge_motor_kw_min | E12: 0.75 | G12: kW | H12: 8
A13: ASG_UNIVERSAL_SYSTEM__ASG-500 | B13: BSG_UNIVERSAL_SYSTEM | C13: ASG-500 | D13: discharge_motor_kw_max | E13: 0.75 | G13: kW | H13: 8
... A77: ASZ_PIN__ASZ-630 | B77: BSZ_PIN | C77: ASZ-630 | D77: door_motor_kw_max | E77: 55 | G77: kW | H77: 13
A78: ASF_AS_HAMMER__ASF-15 | B78: BSF_BS_HAMMER | C78: ASF-15 | D78: discharge_motor_kw | G78: kW | H78: 15
A79: ASF_AS_HAMMER__ASF-15 | B79: BSF_BS_HAMMER | C79: ASF-15 | D79: blower_motor_kw | G79: kW | H79: 15
A80: ASF_AS_HAMMER__ASF-32 | B80: BSF_BS_HAMMER | C80: ASF-32 | D80: discharge_motor_kw | G80: kW | H80: 15
A81: ASF_AS_HAMMER__ASF-32 | B81: BSF_BS_HAMMER | C81: ASF-32 | D81: blower_motor_kw | G81: kW | H81: 15
A82: ASF_AS_HAMMER__AS-200 | B82: BSF_BS_HAMMER | C82: AS-200 | D82: discharge_motor_kw | E82: 0.75 | G82: kW | H82: 15
A83: ASF_AS_HAMMER__AS-200 | B83: BSF_BS_HAMMER | C83: AS-200 | D83: blower_motor_kw | E83: 3 | G83: kW | H83: 15
A84: ASF_AS_HAMMER__AS-320 | B84: BSF_BS_HAMMER | C84: AS-320 | D84: discharge_motor_kw | E84: 0.75 | G84: kW | H84: 15
A85: ASF_AS_HAMMER__AS-320 | B85: BSF_BS_HAMMER | C85: AS-320 | D85: blower_motor_kw | E85: 3 | G85: kW | H85: 15
A86: ASF_AS_HAMMER__AS-400 | B86: BSF_BS_HAMMER | C86: AS-400 | D86: discharge_motor_kw | E86: 0.75 | G86: kW | H86: 15
A87: ASF_AS_HAMMER__AS-400 | B87: BSF_BS_HAMMER | C87: AS-400 | D87: blower_motor_kw | E87: 15 | G87: kW | H87: 15
A88: ASF_AS_HAMMER__AS-630 | B88: BSF_BS_HAMMER | C88: AS-630 | D88: discharge_motor_kw | E88: 1.1 | G88: kW | H88: 15
A89: ASF_AS_HAMMER__AS-630 | B89: BSF_BS_HAMMER | C89: AS-630 | D89: blower_motor_kw | E89: 18.5 | G89: kW | H89: 15
A90: ASF_AS_HAMMER__AS-880 | B90: BSF_BS_HAMMER | C90: AS-880 | D90: discharge_motor_kw | E90: 1.5 | G90: kW | H90: 15
A91: ASF_AS_HAMMER__AS-880 | B91: BSF_BS_HAMMER | C91: AS-880 | D91: blower_motor_kw | E91: 18.5 | G91: kW | H91: 15
A92: ASF_AS_HAMMER__AS-1000 | B92: BSF_BS_HAMMER | C92: AS-1000 | D92: discharge_motor_kw | E92: 1.5 | G92: kW | H92: 15
A93: ASF_AS_HAMMER__AS-1000 | B93: BSF_BS_HAMMER | C93: AS-1000 | D93: blower_motor_kw | E93: 30 | G93: kW | H93: 15
... A119: AS_ROLLER__AS500-4 | B119: BS_ROLLER | C119: AS500-4 | D119: roller_count | E119: 4 | G119: count | H119: 18
A120: ASK_JET__ASK-100 | B120: BSK_JET | C120: ASK-100 | D120: compressed_air_consumption_source_value | E120: 3 | G120: m3/s | H120: 19 | I120: Cần xác minh đơn vị trước khi dùng tính toán.
A121: ASK_JET__ASK-100 | B121: BSK_JET | C121: ASK-100 | D121: compressed_air_consumption_source_unit | F121: m3/s | H121: 19
A122: ASK_JET__ASK-100 | B122: BSK_JET | C122: ASK-100 | D122: pressure_mpa_min | E122: 0.75 | G122: MPa | H122: 19
A123: ASK_JET__ASK-100 | B123: BSK_JET | C123: ASK-100 | D123: pressure_mpa_max | E123: 0.85 | G123: MPa | H123: 19
A124: ASK_JET__ASK-100 | B124: BSK_JET | C124: ASK-100 | D124: electrical_consumption_kw | E124: 20 | G124: kW | H124: 19
A125: ASK_JET__ASK-100 | B125: BSK_JET | C125: ASK-100 | D125: needs_verification | F125: air_consumption_unit | H125: 19
A126: ASK_JET__ASK-200 | B126: BSK_JET | C126: ASK-200 | D126: compressed_air_consumption_source_value | E126: 4.5 | G126: m3/s | H126: 19 | I126: Cần xác minh đơn vị trước khi dùng tính toán.
A127: ASK_JET__ASK-200 | B127: BSK_JET | C127: ASK-200 | D127: compressed_air_consumption_source_unit | F127: m3/s | H127: 19
A128: ASK_JET__ASK-200 | B128: BSK_JET | C128: ASK-200 | D128: pressure_mpa_min | E128: 0.75 | G128: MPa | H128: 19
...

Sheet Selection_Tags
A1: series_code | B1: display_code | C1: tag | D1: note
A2: ASC_COARSE | B2: BSC | C2: coarse | D2: Dùng cho bộ lọc/chọn máy tự động
A3: ASC_COARSE | B3: BSC | C3: pre_crushing | D3: Dùng cho bộ lọc/chọn máy tự động
A4: ASC_COARSE | B4: BSC | C4: large_input | D4: Dùng cho bộ lọc/chọn máy tự động
A5: ASC_COARSE | B5: BSC | C5: impact | D5: Dùng cho bộ lọc/chọn máy tự động
A6: ASC_COARSE | B6: BSC | C6: cutting | D6: Dùng cho bộ lọc/chọn máy tự động
A7: AS_SMALL_HAMMER | B7: BS | C7: food | D7: Dùng cho bộ lọc/chọn máy tự động
A8: AS_SMALL_HAMMER | B8: BS | C8: chemical | D8: Dùng cho bộ lọc/chọn máy tự động
A9: AS_SMALL_HAMMER | B9: BS | C9: pharma | D9: Dùng cho bộ lọc/chọn máy tự động
A10: AS_SMALL_HAMMER | B10: BS | C10: fibrous | D10: Dùng cho bộ lọc/chọn máy tự động
A11: AS_SMALL_HAMMER | B11: BS | C11: hard_material | D11: Dùng cho bộ lọc/chọn máy tự động
A12: AS_SMALL_HAMMER | B12: BS | C12: screen | D12: Dùng cho bộ lọc/chọn máy tự động
... A97: ASF_FITZ_MILL | B97: ASF | C97: granule | D97: Dùng cho bộ lọc/chọn máy tự động

Sheet Corrections
A1: pdf_page | B1: original_text | C1: normalized_value | D1: reason | E1: correction_type | F1: status | G1: review_note
A2: 17 | B2: BSC MÁY NGHIỀN THÔ | C2: BSDF MÁY NGHIỀN BÚA NHIỀU TẦNG | D2: Các model trong bảng là BSDF-350/450/550/750; phần mô tả liền trước và chú thích ảnh đều ghi BSDF. | E2: catalog_layout_typo | F2: Open
A3: 19 | B3: Tiêu thụ khí nén (m3 / giây) | C3: Giữ nguyên đơn vị nguồn: m3/s | D3: Đơn vị trong PDF được bảo toàn; cần kỹ sư xác minh trước khi dùng để thiết kế/chọn máy nén khí. | E3: needs_verification | F3: Open
A4: 20 | B4: BS-200 / BS-400 / BS-500 | C4: Machine ID có prefix series BS_CRYOGENIC | D4: Tên model BS bị trùng với dòng máy nghiền búa; dùng machine_id theo series để tránh xung đột khóa. | E4: database_normalization | F4: Open

Sheet Field_Guide
A1: Sheet | B1: Field | C1: Ý nghĩa / cách cập nhật | D1: Unit / kiểu dữ liệu | E1: Bắt buộc
A2: Models | B2: machine_id | C2: Khóa duy nhất. Hiện được đồng bộ theo series_code + tên model A-series. | D2: text | E2: Yes
A3: Models | B3: series_code | C3: Mã dòng máy nội bộ; hiện giữ mã gốc để ổn định cấu trúc database. | D3: text | E3: Yes
A4: Models | B4: model | C4: Tên model hiển thị. Quy ước hiện tại: chữ cái đầu B đổi thành A. | D4: text | E4: Yes
A5: Models | B5: active | C5: TRUE nếu model đang sử dụng. | D5: boolean | E5: Yes
A6: Models | B6: capacity_min_kg_h / max | C6: Dải công suất. | D6: kg/h | E6: Recommended
A7: Models | B7: fineness_min / max | C7: Dải độ mịn, đọc cùng fineness_unit. | D7: number | E7: Recommended
A8: Extra_Specs | B8: spec_key | C8: Thông số riêng của từng công nghệ. | D8: text | E8: Yes
A9: Corrections | B9: status | C9: Trạng thái xác minh dữ liệu nguồn. | D9: list | E9: Yes
A10: Materials | B10: status | C10: Chỉ dùng tự động các thuộc tính/tương thích có status=Verified. | D10: list | E10: Yes
A11: Material_Series_Map | B11: score_adjustment | C11: Điểm điều chỉnh cho series theo material_id; không thay thế hard filter kỹ thuật. | D11: points | E11: Yes
A12: AI_Config | B12: value | C12: Các trọng số và guardrail có thể cấu hình trước khi đưa vào production. | D12: mixed | E12: Yes
... A17: AI_Selection_Test | B17: total_score | C17: Điểm test = technical score + material adjustment, giới hạn 0–100. | D17: points | E17: Derived

Sheet Update_Log
A1: version | B1: date | C1: editor | D1: sheet | E1: record_id | F1: change_type | G1: description | H1: verified
A2: 1.0 | B2: 2026-09-24 | C2: OpenAI / DTC Product | D2: All | E2: Initial | F2: Created | G2: Tạo workbook editable từ database máy nghiền. | H2: Yes
A3: 1.1 | B3: 2026-09-24 | C3: DTC Product | D3: Models / Extra_Specs | E3: All models | F3: Updated | G3: Đổi chữ cái đầu tiên của toàn bộ tên model từ B thành A và đồng bộ machine_id. | H3: Yes
A4: 2.0 | B4: 2026-09-24 | C4: DTC Product | D4: AI-ready sheets | E4: AI module | F4: Updated | G4: Bổ sung Materials, Material_Series_Map, AI_Config, Selection_Rules, AI_Field_Map, AI_Intents, AI_Prompt, Chat_Examples và AI_Selection_Test để hỗ trợ Chat với trợ lý AI. | H4: Yes
A5: 2.1 | B5: 2026-09-25 | C5: DTC Product / Claude | D5: Series / Models / Extra_Specs / Selection_Tags / Material_Series_Map | E5: All series | F5: Updated | G5: Hoàn tất quy ước đổi B->A còn sót ở seriesCode/displayCode (bản 1.1 trước đó mới đổi model, series code bị bỏ sót) và đồng bộ machine_id/seriesCode liên quan ở Models, Extra_Specs, Selection_Tags, Material_Series_Map. | H5: Yes
A6: 2.2.3 | B6: 2026-09-25 | C6: DTC Product / Claude | D6: Series | E6: All series (trừ ASK) | F6: Updated | G6: Cập nhật tên tiếng Anh (name_en) 10/11 dòng máy theo tên chuẩn mới do DTC cung cấp (VD "ASC Series Coarse Crusher", "ASP Series Ultra-fine Pulverizer Set"...). ASK (Jet Mill) giữ nguyên vì không có trong danh sách cung cấp. | H6: Yes

Sheet Lists
A1: series_code | B1: fineness_unit | C1: correction_status | D1: active
A2: ASC_COARSE | B2: mm | C2: Open | D2: TRUE
A3: AS_SMALL_HAMMER | B3: mesh | C3: Verified | D3: FALSE
A4: ASU_UNIVERSAL | B4: µm | C4: Resolved
A5: ASG_UNIVERSAL_SYSTEM
A6: ASP_ULTRAFINE
A7: ASZ_PIN
A8: ASF_AS_HAMMER
A9: ASDF_MULTISTAGE
A10: AS_ROLLER
A11: ASK_JET
A12: AS_CRYOGENIC

Sheet Materials
A1: material_id | B1: name_vi | C1: name_en | D1: category | E1: hardness | F1: fibrous | G1: oily | H1: sticky_or_paste | I1: wet | J1: heat_sensitive | K1: brittle | L1: crystalline | M1: source_candidate_series | N1: source_basis | O1: status | P1: notes
A2: SESAME | B2: Vừng | C2: Sesame | D2: food | F2: FALSE | G2: TRUE | H2: FALSE | I2: FALSE | K2: FALSE | L2: FALSE | M2: AS_ROLLER | N2: PDF p.18 | O2: Verified | P2: PDF nêu vừng là ví dụ nguyên liệu dầu phù hợp máy nghiền con lăn.
A3: PEANUT | B3: Lạc / Đậu phộng | C3: Peanut | D3: food | F3: FALSE | G3: TRUE | H3: FALSE | I3: FALSE | K3: FALSE | L3: FALSE | M3: AS_ROLLER | N3: PDF p.18 | O3: Verified | P3: PDF nêu lạc/đậu phộng là ví dụ nguyên liệu dầu phù hợp máy nghiền con lăn.
A4: ALMOND | B4: Hạnh nhân | C4: Almond | D4: food | F4: FALSE | G4: TRUE | H4: FALSE | I4: FALSE | K4: FALSE | L4: FALSE | M4: AS_ROLLER | N4: PDF p.18 | O4: Verified | P4: PDF nêu hạnh nhân là ví dụ nguyên liệu dầu phù hợp máy nghiền con lăn.
A5: SPICE_POWDER | B5: Bột gia vị | C5: Spice powder | D5: food | F5: FALSE | I5: FALSE | K5: FALSE | L5: FALSE | M5: ASZ_PIN | N5: PDF p.12 | O5: Verified | P5: Loại A của BSZ được mô tả phù hợp bột có độ chảy kém như bột gia vị.
A6: CACAO | B6: Cacao | C6: Cacao | D6: food | F6: FALSE | H6: TRUE | K6: FALSE | L6: FALSE | M6: ASZ_PIN | N6: PDF p.13 | O6: Verified | P6: PDF nêu BSZ có thể phù hợp sản phẩm dạng nhão như bột mịn cacao.
A7: FRUIT | B7: Trái cây | C7: Fruit | D7: food | F7: FALSE | H7: FALSE | J7: TRUE | K7: FALSE | L7: FALSE | M7: AS_CRYOGENIC | N7: PDF p.20 | O7: Verified | P7: PDF nêu máy nghiền làm lạnh dùng cho vật liệu nhạy nhiệt như trái cây.
A8: VEGETABLE | B8: Rau | C8: Vegetable | D8: food | F8: FALSE | H8: FALSE | J8: TRUE | K8: FALSE | L8: FALSE | M8: AS_CRYOGENIC | N8: PDF p.20 | O8: Verified | P8: PDF nêu máy nghiền làm lạnh dùng cho vật liệu nhạy nhiệt như rau.
A9: HERB | B9: Thảo mộc | C9: Herb | D9: food/pharma | F9: TRUE | H9: FALSE | J9: TRUE | K9: FALSE | L9: FALSE | M9: AS_CRYOGENIC | N9: PDF p.20 | O9: Verified | P9: PDF nêu máy nghiền làm lạnh dùng cho thảo mộc; fibrous là trường để người dùng xác minh thêm.
A10: MEDICINE | B10: Dược liệu / Thuốc | C10: Medicine | D10: pharma | F10: FALSE | H10: FALSE | J10: TRUE | K10: FALSE | L10: FALSE | M10: AS_CRYOGENIC | N10: PDF p.20 | O10: Verified | P10: PDF nêu máy nghiền làm lạnh dùng cho thuốc.
A11: PLASTIC | B11: Nhựa | C11: Plastic | D11: industrial | F11: FALSE | H11: FALSE | J11: TRUE | K11: FALSE | L11: FALSE | M11: AS_CRYOGENIC | N11: PDF p.20 | O11: Verified | P11: PDF nêu máy nghiền làm lạnh dùng cho nhựa.
A12: RUBBER | B12: Cao su | C12: Rubber | D12: industrial | F12: FALSE | H12: FALSE | J12: TRUE | K12: FALSE | L12: FALSE | M12: AS_CRYOGENIC | N12: PDF p.20 | O12: Verified | P12: PDF nêu máy nghiền làm lạnh dùng cho cao su.
A13: PEPPER | B13: Tiêu | C13: Pepper | D13: food | N13: User example | O13: Needs validation | P13: Được thêm để phục vụ chatbot theo ví dụ sử dụng; đặc tính nguyên liệu cần DTC xác minh.
A14: TEA | B14: Trà | C14: Tea | D14: food | N14: App use case | O14: Needs validation | P14: Được thêm để thuận tiện nhập liệu; đặc tính nghiền cần DTC xác minh theo từng loại trà.
A15: SUGAR | B15: Đường | C15: Sugar | D15: food | N15: App use case | O15: Needs validation | P15: Được thêm để thuận tiện nhập liệu; đặc tính và công nghệ phù hợp cần xác minh.

Sheet Material_Series_Map
A1: material_id | B1: series_code | C1: score_adjustment | D1: basis_type | E1: reason_vi | F1: source_basis | G1: status
A2: SESAME | B2: AS_ROLLER | C2: 20 | D2: source_supported | E2: Nguyên liệu dầu; PDF nêu vừng là ví dụ ứng dụng máy nghiền con lăn. | F2: PDF p.18 | G2: Verified
A3: PEANUT | B3: AS_ROLLER | C3: 20 | D3: source_supported | E3: Nguyên liệu dầu; PDF nêu lạc/đậu phộng là ví dụ ứng dụng máy nghiền con lăn. | F3: PDF p.18 | G3: Verified
A4: ALMOND | B4: AS_ROLLER | C4: 20 | D4: source_supported | E4: Nguyên liệu dầu; PDF nêu hạnh nhân là ví dụ ứng dụng máy nghiền con lăn. | F4: PDF p.18 | G4: Verified
A5: SPICE_POWDER | B5: ASZ_PIN | C5: 15 | D5: source_supported | E5: BSZ Loại A phù hợp bột chảy kém như bột gia vị. | F5: PDF p.12 | G5: Verified
A6: CACAO | B6: ASZ_PIN | C6: 15 | D6: source_supported | E6: BSZ được mô tả phù hợp sản phẩm dạng nhão như bột mịn cacao. | F6: PDF p.13 | G6: Verified
A7: FRUIT | B7: AS_CRYOGENIC | C7: 15 | D7: source_supported | E7: Máy nghiền làm lạnh được nêu cho vật liệu nhạy nhiệt như trái cây. | F7: PDF p.20 | G7: Verified
A8: VEGETABLE | B8: AS_CRYOGENIC | C8: 15 | D8: source_supported | E8: Máy nghiền làm lạnh được nêu cho vật liệu nhạy nhiệt như rau. | F8: PDF p.20 | G8: Verified
A9: HERB | B9: AS_CRYOGENIC | C9: 15 | D9: source_supported | E9: Máy nghiền làm lạnh được nêu cho thảo mộc. | F9: PDF p.20 | G9: Verified
A10: MEDICINE | B10: AS_CRYOGENIC | C10: 15 | D10: source_supported | E10: Máy nghiền làm lạnh được nêu cho thuốc. | F10: PDF p.20 | G10: Verified
A11: PLASTIC | B11: AS_CRYOGENIC | C11: 15 | D11: source_supported | E11: Máy nghiền làm lạnh được nêu cho nhựa. | F11: PDF p.20 | G11: Verified
A12: RUBBER | B12: AS_CRYOGENIC | C12: 15 | D12: source_supported | E12: Máy nghiền làm lạnh được nêu cho cao su. | F12: PDF p.20 | G12: Verified

Sheet AI_Config
A1: key | B1: value | C1: unit | D1: category | E1: description | F1: editable
A2: capacity_weight | B2: 40 | C2: points | D2: scoring | E2: Điểm khi năng suất mục tiêu nằm trong dải model. | F2: TRUE
A3: input_size_weight | B3: 20 | C3: points | D3: scoring | E3: Điểm khi kích thước đầu vào không vượt giới hạn model; nếu model không có dữ liệu thì không loại và phải cảnh báo. | F3: TRUE
A4: fineness_weight | B4: 40 | C4: points | D4: scoring | E4: Điểm khi độ mịn và đơn vị nằm trong dải model. | F4: TRUE
A5: material_adjustment_min | B5: -30 | C5: points | D5: scoring | E5: Giới hạn dưới điều chỉnh theo vật liệu. | F5: TRUE
A6: material_adjustment_max | B6: 20 | C6: points | D6: scoring | E6: Giới hạn trên điều chỉnh theo vật liệu. | F6: TRUE
A7: candidate_threshold | B7: 80 | C7: points | D7: display | E7: Ngưỡng gợi ý để đánh dấu ứng viên mạnh khi không có cảnh báo loại. | F7: TRUE
A8: ask_if_capacity_missing | B8: TRUE | C8: boolean | D8: dialog | E8: Hỏi lại nếu người dùng chưa cung cấp năng suất cho yêu cầu chọn model. | F8: TRUE
A9: ask_if_fineness_missing | B9: TRUE | C9: boolean | D9: dialog | E9: Hỏi lại nếu người dùng chưa cung cấp độ mịn khi cần chọn model cụ thể. | F9: TRUE
A10: allow_unknown_input_size | B10: TRUE | C10: boolean | D10: guardrail | E10: Không loại model chỉ vì catalogue thiếu input size; trả cảnh báo. | F10: TRUE
A11: no_hallucinated_specs | B11: TRUE | C11: boolean | D11: guardrail | E11: AI không được tự tạo thông số không tồn tại trong database. | F11: FALSE
A12: candidate_not_confirmation | B12: TRUE | C12: boolean | D12: guardrail | E12: Kết quả là ứng viên kỹ thuật; công suất/độ mịn thực tế vẫn cần thử mẫu khi tài liệu không đảm bảo. | F12: FALSE

Sheet Selection_Rules
A1: rule_id | B1: rule_type | C1: input_field | D1: logic | E1: weight_or_value | F1: on_fail | G1: message_vi | H1: basis | I1: status
A2: TECH_CAPACITY | B2: hard_filter | C2: capacity_kg_h | D2: model.capacity_min_kg_h <= value <= model.capacity_max_kg_h | E2: 40 | F2: reject | G2: Năng suất phải nằm trong dải model. | H2: Database Models | I2: Active
A3: TECH_INPUT | B3: hard_filter_with_unknown | C3: input_size_mm | D3: value <= model.input_size_max_mm OR model.input_size_max_mm IS NULL | E3: 20 | F3: warn_if_unknown | G3: Nếu catalogue có giới hạn đầu vào thì phải đáp ứng; thiếu dữ liệu thì giữ model nhưng cảnh báo. | H3: Database Models | I3: Active
A4: TECH_FINENESS | B4: hard_filter | C4: fineness_value + fineness_unit | D4: unit = model.fineness_unit AND min <= value <= max | E4: 40 | F4: reject | G4: Độ mịn phải nằm trong dải và đúng đơn vị của model. | H4: Database Models | I4: Active
A5: MATERIAL_COMPAT | B5: score_adjustment | C5: material_id | D5: lookup Material_Series_Map by material_id + series_code | E5: config | F5: adjust | G5: Điều chỉnh điểm theo dữ liệu tương thích nguyên liệu đã xác minh. | H5: Material_Series_Map | I5: Active
A6: NO_SPEC_GUESS | B6: guardrail | C6: any_missing_spec | D6: do not infer numeric specs | E6: 0 | F6: warn | G6: Không tự suy đoán thông số kỹ thuật bị thiếu. | H6: AI_Config | I6: Active
A7: BSC_PRECRUSH | B7: workflow_hint | C7: input_size_mm | D7: if input too large for fine mill and <100 mm, evaluate ASC coarse crusher as pre-crusher | E7: 0 | F7: suggest_process | G7: Có thể đề xuất nghiền sơ bộ ASC khi phù hợp dải đầu vào của dòng nghiền thô. | H7: PDF p.5 + app logic | I7: Active
A8: ASK_JET_AIR | B8: requirement | C8: series_code=BSK_JET | D8: surface pressure and air consumption requirements | E8: 0 | F8: show_requirement | G8: Dòng ASK cần hiển thị yêu cầu khí nén và cảnh báo đơn vị tiêu thụ khí trong PDF cần xác minh. | H8: PDF p.19 | I8: Active
A9: ASK_CRYO_N2 | B9: requirement | C9: series_code=BS_CRYOGENIC | D9: show liquid nitrogen requirement | E9: 0 | F9: show_requirement | G9: Dòng AS Cryogenic cần nitơ lỏng; không đề xuất mà không nói rõ điều kiện này. | H9: PDF p.20 | I9: Active
A10: REAL_WORLD_TEST | B10: guardrail | C10: final_recommendation | D10: state that actual output depends on material where source says so | E10: 0 | F10: warn | G10: Không coi kết quả database là bảo đảm hiệu suất thực tế; khuyến nghị test mẫu khi cần. | H10: PDF notes | I10: Active

Sheet AI_Field_Map
A1: field_name | B1: synonyms_vi | C1: data_type | D1: canonical_unit | E1: normalization | F1: importance
A2: capacity_kg_h | B2: năng suất|công suất|sản lượng|kg/h|tấn/giờ|t/h | C2: number | D2: kg/h | E2: Convert t/h × 1000 | F2: required_for_selection
A3: material_name | B3: nguyên liệu|vật liệu|sản phẩm|cần nghiền | C3: text | E3: Resolve to Materials.material_id when possible | F3: recommended
A4: input_size_mm | B4: kích thước đầu vào|size đầu vào|nguyên liệu đầu vào|mm đầu vào | C4: number | D4: mm | E4: Normalize to mm | F4: optional_but_useful
A5: fineness_value | B5: độ mịn|mesh|micron|µm|mm đầu ra | C5: number | E5: Read together with fineness_unit | F5: required_for_specific_model
A6: fineness_unit | B6: mesh|micron|µm|um|mm | C6: enum | D6: mesh/µm/mm | E6: Normalize micron/um to µm | F6: required_when_fineness_present
A7: heat_sensitive | B7: nhạy nhiệt|không được nóng|giữ màu|nhiệt độ thấp | C7: boolean | E7: Do not infer TRUE unless user states or material record is Verified | F7: optional
A8: oily | B8: dầu|nhiều dầu|hàm lượng dầu | C8: boolean | E8: Use only when stated or Verified material record | F8: optional
A9: sticky | B9: dính|nhão|paste | C9: boolean | E9: Map paste/nhão to sticky_or_paste | F9: optional
A10: wet | B10: ẩm|ướt|độ ẩm cao | C10: boolean | E10: Do not infer level without value | F10: optional
A11: continuous | B11: liên tục|continuous | C11: boolean | E11: Can influence system preference but not hard-filter unless rule exists | F11: optional
A12: dust_control | B12: hút bụi|không bụi|thu bụi | C12: boolean | E12: Prefer series with verified dust-collection tag | F12: optional

Sheet AI_Intents
A1: intent_id | B1: name_vi | C1: trigger_description | D1: execution | E1: guardrail
A2: select_machine | B2: Chọn máy phù hợp | C2: Người dùng cung cấp nguyên liệu/thông số mục tiêu và muốn tìm dòng/model. | D2: Extract fields -> deterministic filter/score -> explain candidates | E2: Không trả model nếu dữ liệu bắt buộc thiếu; hỏi lại.
A3: compare_models | B3: So sánh model | C3: Người dùng nêu từ 2 model trở lên. | D3: Lookup exact records -> compare common fields + extra specs | E3: Không tự bổ sung thông số thiếu.
A4: lookup_spec | B4: Tra thông số | C4: Hỏi thông số của một model. | D4: Exact lookup by model/machine_id | E4: Nếu model mơ hồ, yêu cầu chọn series.
A5: explain_series | B5: Giải thích dòng máy | C5: Hỏi công nghệ/nguyên lý/ứng dụng. | D5: Use Series + Selection_Tags + source notes | E5: Phân biệt mô tả nguồn và logic app.
A6: convert_fineness | B6: Quy đổi độ mịn | C6: Hỏi mesh/µm/mm. | D6: Use app converter / validated conversion table | E6: Nêu rằng mesh↔µm là giá trị gần đúng nếu dùng bảng quy đổi.
A7: process_hint | B7: Gợi ý quy trình | C7: Yêu cầu nghiền sơ bộ, hút bụi, khí nén, nitơ... | D7: Use requirements/rules and candidate series | E7: Không thiết kế hệ thống ngoài dữ liệu nếu chưa có thông số.

Sheet AI_Prompt
A1: section | B1: instruction
A2: ROLE | B2: Bạn là trợ lý kỹ thuật cho module Máy nghiền của DTC Product. Nhiệm vụ là hiểu yêu cầu người dùng, truy vấn database và giải thích kết quả.
A3: SOURCE_OF_TRUTH | B3: Thông số model chỉ được lấy từ Models và Extra_Specs. Ứng dụng/nguyên lý lấy từ Series. Tương thích nguyên liệu lấy từ Materials + Material_Series_Map khi status=Verified.
A4: NO_HALLUCINATION | B4: Không tự tạo model, công suất, độ mịn, motor, kích thước, áp suất hoặc tính năng không có trong database.
A5: SELECTION | B5: Khi chọn máy, trước hết áp dụng hard filters về năng suất, kích thước đầu vào (nếu có dữ liệu), độ mịn/đơn vị; sau đó mới cộng/trừ điểm vật liệu.
A6: MISSING_INPUT | B6: Nếu thiếu thông tin quan trọng khiến không thể chọn model cụ thể, hỏi ngắn gọn phần còn thiếu thay vì đoán.
A7: OUTPUT | B7: Trả tối đa 3 ứng viên đầu tiên. Với mỗi ứng viên: model, dòng máy, dải công suất, độ mịn, lý do khớp, cảnh báo/điểm cần xác minh.
A8: CONFIDENCE | B8: Không gọi kết quả là 'đảm bảo phù hợp'. Dùng 'ứng viên phù hợp theo database' và nêu cần test mẫu khi hiệu suất phụ thuộc nguyên liệu.
A9: NO_MATCH | B9: Nếu không có model đáp ứng đầy đủ, nói rõ không có exact match; có thể hiển thị near-match nhưng phải chỉ rõ điều kiện nào không đạt.
A10: SPECIAL | B10: ASK/jet mill: hiển thị yêu cầu khí nén và cảnh báo đơn vị tiêu thụ khí nguồn cần xác minh. Cryogenic: nói rõ cần nitơ lỏng.

Sheet Chat_Examples
A1: example_id | B1: user_message | C1: intent | D1: structured_query_example | E1: expected_behavior
A2: EX-001 | B2: Tôi cần nghiền tiêu 1 tấn/giờ, độ mịn 50 mesh, đầu vào 15 mm. | C2: select_machine | D2: {"material_name":"Tiêu","capacity_kg_h":1000,"fineness_value":50,"fineness_unit":"mesh","input_size_mm":15} | E2: PEPPER đang Needs validation: chỉ lọc kỹ thuật theo model; không tự suy luận đặc tính tiêu.
A3: EX-002 | B3: Tôi cần nghiền vừng 200 kg/h khoảng 20 mesh. | C3: select_machine | D3: {"material_id":"SESAME","capacity_kg_h":200,"fineness_value":20,"fineness_unit":"mesh"} | E3: Có thể cộng điểm BS_ROLLER vì compatibility đã Verified từ PDF.
A4: EX-003 | B4: So sánh ASP-450 và ASZ-450. | C4: compare_models | D4: {"models":["ASP-450","ASZ-450"]} | E4: Tra cứu exact model rồi so sánh; không suy đoán trường trống.
A5: EX-004 | B5: ASK-300 cần khí nén bao nhiêu? | C5: lookup_spec | D5: {"model":"ASK-300","fields":["pressure","compressed_air_consumption"]} | E5: Hiển thị dữ liệu nguồn và cảnh báo đơn vị tiêu thụ khí cần xác minh.

Sheet AI_Selection_Test
A1: DTC PRODUCT – AI SELECTION ENGINE TEST
A3: Input | B3: Value | C3: Unit / Note
A4: Capacity | B4: 1000 | C4: kg/h
A5: Input size | B5: 15 | C5: mm (để trống nếu chưa biết)
A6: Fineness | B6: 50
A7: Fineness unit | B7: mesh | C7: mesh / µm / mm
A8: Material ID | B8: PEPPER | C8: Chọn từ Materials.material_id
A9: Kết quả bên dưới là bộ lọc kỹ thuật thử nghiệm. Hãy filter cột Status và sort Total Score giảm dần. Material score chỉ dùng các dòng Verified.
A10: machine_id | B10: model | C10: series_code | D10: capacity_min | E10: capacity_max | F10: input_max_mm | G10: fineness_min | H10: fineness_max | I10: unit | J10: capacity_match | K10: input_match | L10: fineness_match | M10: technical_score | N10: material_adj | O10: total_score | P10: status
A11: ASC_COARSE__ASC-200 | B11: ASC-200 | C11: ASC_COARSE | D11: =Models!G2 | E11: =Models!H2 | F11: =Models!I2 | G11: =Models!K2 | H11: =Models!L2 | I11: mm | J11: =IF(AND($B$4>=D11,$B$4<=E11),1,0) | K11: =IF($B$5="",1,IF(F11="",1,IF($B$5<=F11,1,0))) | L11: =IF($B$6="",1,IF(AND($B$7=I11,$B$6>=G11,$B$6<=H11),1,0)) | M11: =J11*40+K11*20+L11*40 | N11: =IF($B$8="",0,SUMIFS(Material_Series_Map!$C$2:$C$300,Material_Series_Map!$A$2:$A$300,$B$8,Material_Series_Map!$B$2:$B$300,C11,Material_Series_Map!$G$2:$G$300,"Verified")) | O11: =MIN(100,MAX(0,M11+N11)) | P11: NO MATCH
A12: ASC_COARSE__ASC-300 | B12: ASC-300 | C12: ASC_COARSE | D12: =Models!G3 | E12: =Models!H3 | F12: =Models!I3 | G12: =Models!K3 | H12: =Models!L3 | I12: mm | J12: =IF(AND($B$4>=D12,$B$4<=E12),1,0) | K12: =IF($B$5="",1,IF(F12="",1,IF($B$5<=F12,1,0))) | L12: =IF($B$6="",1,IF(AND($B$7=I12,$B$6>=G12,$B$6<=H12),1,0)) | M12: =J12*40+K12*20+L12*40 | N12: =IF($B$8="",0,SUMIFS(Material_Series_Map!$C$2:$C$300,Material_Series_Map!$A$2:$A$300,$B$8,Material_Series_Map!$B$2:$B$300,C12,Material_Series_Map!$G$2:$G$300,"Verified")) | O12: =MIN(100,MAX(0,M12+N12)) | P12: NO MATCH
A13: ASC_COARSE__ASC-400 | B13: ASC-400 | C13: ASC_COARSE | D13: =Models!G4 | E13: =Models!H4 | F13: =Models!I4 | G13: =Models!K4 | H13: =Models!L4 | I13: mm | J13: =IF(AND($B$4>=D13,$B$4<=E13),1,0) | K13: =IF($B$5="",1,IF(F13="",1,IF($B$5<=F13,1,0))) | L13: =IF($B$6="",1,IF(AND($B$7=I13,$B$6>=G13,$B$6<=H13),1,0)) | M13: =J13*40+K13*20+L13*40 | N13: =IF($B$8="",0,SUMIFS(Material_Series_Map!$C$2:$C$300,Material_Series_Map!$A$2:$A$300,$B$8,Material_Series_Map!$B$2:$B$300,C13,Material_Series_Map!$G$2:$G$300,"Verified")) | O13: =MIN(100,MAX(0,M13+N13)) | P13: NO MATCH
A14: ASC_COARSE__ASC-600 | B14: ASC-600 | C14: ASC_COARSE | D14: =Models!G5 | E14: =Models!H5 | F14: =Models!I5 | G14: =Models!K5 | H14: =Models!L5 | I14: mm | J14: =IF(AND($B$4>=D14,$B$4<=E14),1,0) | K14: =IF($B$5="",1,IF(F14="",1,IF($B$5<=F14,1,0))) | L14: =IF($B$6="",1,IF(AND($B$7=I14,$B$6>=G14,$B$6<=H14),1,0)) | M14: =J14*40+K14*20+L14*40 | N14: =IF($B$8="",0,SUMIFS(Material_Series_Map!$C$2:$C$300,Material_Series_Map!$A$2:$A$300,$B$8,Material_Series_Map!$B$2:$B$300,C14,Material_Series_Map!$G$2:$G$300,"Verified")) | O14: =MIN(100,MAX(0,M14+N14)) | P14: NO MATCH
A15: ASC_COARSE__ASC-1000 | B15: ASC-1000 | C15: ASC_COARSE | D15: =Models!G6 | E15: =Models!H6 | F15: =Models!I6 | G15: =Models!K6 | H15: =Models!L6 | I15: mm | J15: =IF(AND($B$4>=D15,$B$4<=E15),1,0) | K15: =IF($B$5="",1,IF(F15="",1,IF($B$5<=F15,1,0))) | L15: =IF($B$6="",1,IF(AND($B$7=I15,$B$6>=G15,$B$6<=H15),1,0)) | M15: =J15*40+K15*20+L15*40 | N15: =IF($B$8="",0,SUMIFS(Material_Series_Map!$C$2:$C$300,Material_Series_Map!$A$2:$A$300,$B$8,Material_Series_Map!$B$2:$B$300,C15,Material_Series_Map!$G$2:$G$300,"Verified")) | O15: =MIN(100,MAX(0,M15+N15)) | P15: NO MATCH
A16: AS_SMALL_HAMMER__AS-180 | B16: AS-180 | C16: AS_SMALL_HAMMER | D16: =Models!G7 | E16: =Models!H7 | F16: =Models!I7 | G16: =Models!K7 | H16: =Models!L7 | I16: mesh | J16: =IF(AND($B$4>=D16,$B$4<=E16),1,0) | K16: =IF($B$5="",1,IF(F16="",1,IF($B$5<=F16,1,0))) | L16: =IF($B$6="",1,IF(AND($B$7=I16,$B$6>=G16,$B$6<=H16),1,0)) | M16: =J16*40+K16*20+L16*40 | N16: =IF($B$8="",0,SUMIFS(Material_Series_Map!$C$2:$C$300,Material_Series_Map!$A$2:$A$300,$B$8,Material_Series_Map!$B$2:$B$300,C16,Material_Series_Map!$G$2:$G$300,"Verified")) | O16: =MIN(100,MAX(0,M16+N16)) | P16: NO MATCH
A17: AS_SMALL_HAMMER__AS-250 | B17: AS-250 | C17: AS_SMALL_HAMMER | D17: =Models!G8 | E17: =Models!H8 | F17: =Models!I8 | G17: =Models!K8 | H17: =Models!L8 | I17: mesh | J17: =IF(AND($B$4>=D17,$B$4<=E17),1,0) | K17: =IF($B$5="",1,IF(F17="",1,IF($B$5<=F17,1,0))) | L17: =IF($B$6="",1,IF(AND($B$7=I17,$B$6>=G17,$B$6<=H17),1,0)) | M17: =J17*40+K17*20+L17*40 | N17: =IF($B$8="",0,SUMIFS(Material_Series_Map!$C$2:$C$300,Material_Series_Map!$A$2:$A$300,$B$8,Material_Series_Map!$B$2:$B$300,C17,Material_Series_Map!$G$2:$G$300,"Verified")) | O17: =MIN(100,MAX(0,M17+N17)) | P17: NO MATCH
A18: AS_SMALL_HAMMER__AS-350 | B18: AS-350 | C18: AS_SMALL_HAMMER | D18: =Models!G9 | E18: =Models!H9 | F18: =Models!I9 | G18: =Models!K9 | H18: =Models!L9 | I18: mesh | J18: =IF(AND($B$4>=D18,$B$4<=E18),1,0) | K18: =IF($B$5="",1,IF(F18="",1,IF($B$5<=F18,1,0))) | L18: =IF($B$6="",1,IF(AND($B$7=I18,$B$6>=G18,$B$6<=H18),1,0)) | M18: =J18*40+K18*20+L18*40 | N18: =IF($B$8="",0,SUMIFS(Material_Series_Map!$C$2:$C$300,Material_Series_Map!$A$2:$A$300,$B$8,Material_Series_Map!$B$2:$B$300,C18,Material_Series_Map!$G$2:$G$300,"Verified")) | O18: =MIN(100,MAX(0,M18+N18)) | P18: NO MATCH
A19: ASU_UNIVERSAL__ASU-20 | B19: ASU-20 | C19: ASU_UNIVERSAL | D19: =Models!G10 | E19: =Models!H10 | F19: =Models!I10 | G19: =Models!K10 | H19: =Models!L10 | I19: mesh | J19: =IF(AND($B$4>=D19,$B$4<=E19),1,0) | K19: =IF($B$5="",1,IF(F19="",1,IF($B$5<=F19,1,0))) | L19: =IF($B$6="",1,IF(AND($B$7=I19,$B$6>=G19,$B$6<=H19),1,0)) | M19: =J19*40+K19*20+L19*40 | N19: =IF($B$8="",0,SUMIFS(Material_Series_Map!$C$2:$C$300,Material_Series_Map!$A$2:$A$300,$B$8,Material_Series_Map!$B$2:$B$300,C19,Material_Series_Map!$G$2:$G$300,"Verified")) | O19: =MIN(100,MAX(0,M19+N19)) | P19: NO MATCH
A20: ASU_UNIVERSAL__ASU-30 | B20: ASU-30 | C20: ASU_UNIVERSAL | D20: =Models!G11 | E20: =Models!H11 | F20: =Models!I11 | G20: =Models!K11 | H20: =Models!L11 | I20: mesh | J20: =IF(AND($B$4>=D20,$B$4<=E20),1,0) | K20: =IF($B$5="",1,IF(F20="",1,IF($B$5<=F20,1,0))) | L20: =IF($B$6="",1,IF(AND($B$7=I20,$B$6>=G20,$B$6<=H20),1,0)) | M20: =J20*40+K20*20+L20*40 | N20: =IF($B$8="",0,SUMIFS(Material_Series_Map!$C$2:$C$300,Material_Series_Map!$A$2:$A$300,$B$8,Material_Series_Map!$B$2:$B$300,C20,Material_Series_Map!$G$2:$G$300,"Verified")) | O20: =MIN(100,MAX(0,M20+N20)) | P20: NO MATCH
A21: ASU_UNIVERSAL__ASU-40 | B21: ASU-40 | C21: ASU_UNIVERSAL | D21: =Models!G12 | E21: =Models!H12 | F21: =Models!I12 | G21: =Models!K12 | H21: =Models!L12 | I21: mesh | J21: =IF(AND($B$4>=D21,$B$4<=E21),1,0) | K21: =IF($B$5="",1,IF(F21="",1,IF($B$5<=F21,1,0))) | L21: =IF($B$6="",1,IF(AND($B$7=I21,$B$6>=G21,$B$6<=H21),1,0)) | M21: =J21*40+K21*20+L21*40 | N21: =IF($B$8="",0,SUMIFS(Material_Series_Map!$C$2:$C$300,Material_Series_Map!$A$2:$A$300,$B$8,Material_Series_Map!$B$2:$B$300,C21,Material_Series_Map!$G$2:$G$300,"Verified")) | O21: =MIN(100,MAX(0,M21+N21)) | P21: NO MATCH
A22: ASU_UNIVERSAL__ASU-50 | B22: ASU-50 | C22: ASU_UNIVERSAL | D22: =Models!G13 | E22: =Models!H13 | F22: =Models!I13 | G22: =Models!K13 | H22: =Models!L13 | I22: mesh | J22: =IF(AND($B$4>=D22,$B$4<=E22),1,0) | K22: =IF($B$5="",1,IF(F22="",1,IF($B$5<=F22,1,0))) | L22: =IF($B$6="",1,IF(AND($B$7=I22,$B$6>=G22,$B$6<=H22),1,0)) | M22: =J22*40+K22*20+L22*40 | N22: =IF($B$8="",0,SUMIFS(Material_Series_Map!$C$2:$C$300,Material_Series_Map!$A$2:$A$300,$B$8,Material_Series_Map!$B$2:$B$300,C22,Material_Series_Map!$G$2:$G$300,"Verified")) | O22: =MIN(100,MAX(0,M22+N22)) | P22: NO MATCH
